Workbook

Sheet Maternal Mortality for Aug Data
A1: Residence State | B1: FIPS Code | C1: Year | D1: Maternal Deaths | E1: Population | F1: Crude Rate (CR) | G1: CR Unreliable? | H1: Births | I1: Maternal Mortality Rate | J1: Land Area (sq mi) | K1: Population Density
A2: Alabama | B2: 1 | C2: 2018 | D2: 21 | E2: 4887871 | F2: 0.4 | H2: 57761 | I2: =(D2/H2)*100000 -> 36.356711 | J2: =INDEX('Land Area'!$C:$C, MATCH($B2, 'Land Area'!$B:$B, 0)) -> 52420 | K2: =E2/J2 -> 93.244391
A3: Alabama | B3: 1 | C3: 2019 | D3: 21 | E3: 4903185 | F3: 0.4 | H3: 58615 | I3: =(D3/H3)*100000 -> 35.827007 | J3: =INDEX('Land Area'!$C:$C, MATCH($B3, 'Land Area'!$B:$B, 0)) -> 52420 | K3: =E3/J3 -> 93.536532
A4: Alabama | B4: 1 | C4: 2020 | D4: 21 | E4: 4921532 | F4: 0.4 | H4: 57647 | I4: =(D4/H4)*100000 -> 36.428609 | J4: =INDEX('Land Area'!$C:$C, MATCH($B4, 'Land Area'!$B:$B, 0)) -> 52420 | K4: =E4/J4 -> 93.886532
A5: Alabama | B5: 1 | C5: 2021 | D5: 33 | E5: 5039877 | F5: 0.7 | H5: 58054 | I5: =(D5/H5)*100000 -> 56.843628 | J5: =INDEX('Land Area'!$C:$C, MATCH($B5, 'Land Area'!$B:$B, 0)) -> 52420 | K5: =E5/J5 -> 96.144163
A6: Alabama | B6: 1 | C6: 2022 | D6: 16 | E6: 5074296 | F6: 0.3 | G6: Yes | H6: 58149 | I6: =(D6/H6)*100000 -> 27.51552 | J6: =INDEX('Land Area'!$C:$C, MATCH($B6, 'Land Area'!$B:$B, 0)) -> 52420 | K6: =E6/J6 -> 96.800763
A7: Alabama | B7: 1 | C7: 2023 | D7: 11 | E7: 5108468 | F7: 0.2 | G7: Yes | H7: 57858 | I7: =(D7/H7)*100000 -> 19.012064 | J7: =INDEX('Land Area'!$C:$C, MATCH($B7, 'Land Area'!$B:$B, 0)) -> 52420 | K7: =E7/J7 -> 97.452652
A8: Alaska | B8: 2 | C8: 2018 | E8: 737438 | H8: 10086 | J8: =INDEX('Land Area'!$C:$C, MATCH($B8, 'Land Area'!$B:$B, 0)) -> 571951 | K8: =E8/J8 -> 1.2893377
A9: Alaska | B9: 2 | C9: 2019 | E9: 731545 | H9: 9822 | J9: =INDEX('Land Area'!$C:$C, MATCH($B9, 'Land Area'!$B:$B, 0)) -> 571951 | K9: =E9/J9 -> 1.2790344
A10: Alaska | B10: 2 | C10: 2020 | D10: 0 | E10: 731158 | F10: 0 | G10: Yes | H10: 9469 | I10: =(D10/H10)*100000 -> 0 | J10: =INDEX('Land Area'!$C:$C, MATCH($B10, 'Land Area'!$B:$B, 0)) -> 571951 | K10: =E10/J10 -> 1.2783578
A11: Alaska | B11: 2 | C11: 2021 | E11: 732673 | H11: 9367 | J11: =INDEX('Land Area'!$C:$C, MATCH($B11, 'Land Area'!$B:$B, 0)) -> 571951 | K11: =E11/J11 -> 1.2810066
A12: Alaska | B12: 2 | C12: 2022 | E12: 733583 | H12: 9359 | J12: =INDEX('Land Area'!$C:$C, MATCH($B12, 'Land Area'!$B:$B, 0)) -> 571951 | K12: =E12/J12 -> 1.2825976
A13: Alaska | B13: 2 | C13: 2023 | E13: 733406 | H13: 9015 | J13: =INDEX('Land Area'!$C:$C, MATCH($B13, 'Land Area'!$B:$B, 0)) -> 571951 | K13: =E13/J13 -> 1.2822882
A14: Arizona | B14: 4 | C14: 2018 | D14: 18 | E14: 7171646 | F14: 0.3 | G14: Yes | H14: 80723 | I14: =(D14/H14)*100000 -> 22.298478 | J14: =INDEX('Land Area'!$C:$C, MATCH($B14, 'Land Area'!$B:$B, 0)) -> 113594 | K14: =E14/J14 -> 63.134021
A15: Arizona | B15: 4 | C15: 2019 | D15: 20 | E15: 7278717 | F15: 0.3 | H15: 79375 | I15: =(D15/H15)*100000 -> 25.19685 | J15: =INDEX('Land Area'!$C:$C, MATCH($B15, 'Land Area'!$B:$B, 0)) -> 113594 | K15: =E15/J15 -> 64.076597
A16: Arizona | B16: 4 | C16: 2020 | D16: 29 | E16: 7421401 | F16: 0.4 | H16: 76947 | I16: =(D16/H16)*100000 -> 37.688279 | J16: =INDEX('Land Area'!$C:$C, MATCH($B16, 'Land Area'!$B:$B, 0)) -> 113594 | K16: =E16/J16 -> 65.332685
A17: Arizona | B17: 4 | C17: 2021 | D17: 32 | E17: 7276316 | F17: 0.4 | H17: 77916 | I17: =(D17/H17)*100000 -> 41.06987 | J17: =INDEX('Land Area'!$C:$C, MATCH($B17, 'Land Area'!$B:$B, 0)) -> 113594 | K17: =E17/J17 -> 64.055461
A18: Arizona | B18: 4 | C18: 2022 | D18: 19 | E18: 7359197 | F18: 0.3 | G18: Yes | H18: 78547 | I18: =(D18/H18)*100000 -> 24.189339 | J18: =INDEX('Land Area'!$C:$C, MATCH($B18, 'Land Area'!$B:$B, 0)) -> 113594 | K18: =E18/J18 -> 64.785085
A19: Arizona | B19: 4 | C19: 2023 | D19: 19 | E19: 7431344 | F19: 0.3 | G19: Yes | H19: 78096 | I19: =(D19/H19)*100000 -> 24.329031 | J19: =INDEX('Land Area'!$C:$C, MATCH($B19, 'Land Area'!$B:$B, 0)) -> 113594 | K19: =E19/J19 -> 65.420216
A20: Arkansas | B20: 5 | C20: 2018 | D20: 17 | E20: 3013825 | F20: 0.6 | G20: Yes | H20: 37018 | I20: =(D20/H20)*100000 -> 45.923605 | J20: =INDEX('Land Area'!$C:$C, MATCH($B20, 'Land Area'!$B:$B, 0)) -> 53179 | K20: =E20/J20 -> 56.673217
A21: Arkansas | B21: 5 | C21: 2019 | D21: 12 | E21: 3017804 | F21: 0.4 | G21: Yes | H21: 36564 | I21: =(D21/H21)*100000 -> 32.819166 | J21: =INDEX('Land Area'!$C:$C, MATCH($B21, 'Land Area'!$B:$B, 0)) -> 53179 | K21: =E21/J21 -> 56.74804
A22: Arkansas | B22: 5 | C22: 2020 | D22: 15 | E22: 3030522 | F22: 0.5 | G22: Yes | H22: 35251 | I22: =(D22/H22)*100000 -> 42.551984 | J22: =INDEX('Land Area'!$C:$C, MATCH($B22, 'Land Area'!$B:$B, 0)) -> 53179 | K22: =E22/J22 -> 56.987194
A23: Arkansas | B23: 5 | C23: 2021 | D23: 19 | E23: 3025891 | F23: 0.6 | G23: Yes | H23: 35965 | I23: =(D23/H23)*100000 -> 52.829139 | J23: =INDEX('Land Area'!$C:$C, MATCH($B23, 'Land Area'!$B:$B, 0)) -> 53179 | K23: =E23/J23 -> 56.900111
A24: Arkansas | B24: 5 | C24: 2022 | E24: 3045637 | H24: 35471 | J24: =INDEX('Land Area'!$C:$C, MATCH($B24, 'Land Area'!$B:$B, 0)) -> 53179 | K24: =E24/J24 -> 57.271423
A25: Arkansas | B25: 5 | C25: 2023 | D25: 11 | E25: 3067732 | F25: 0.4 | G25: Yes | H25: 35264 | I25: =(D25/H25)*100000 -> 31.193285 | J25: =INDEX('Land Area'!$C:$C, MATCH($B25, 'Land Area'!$B:$B, 0)) -> 53179 | K25: =E25/J25 -> 57.686906
A26: California | B26: 6 | C26: 2018 | D26: 53 | E26: 39557045 | F26: 0.1 | H26: 454920 | I26: =(D26/H26)*100000 -> 11.6504 | J26: =INDEX('Land Area'!$C:$C, MATCH($B26, 'Land Area'!$B:$B, 0)) -> 155779 | K26: =E26/J26 -> 253.93054
A27: California | B27: 6 | C27: 2019 | D27: 50 | E27: 39512223 | F27: 0.1 | H27: 446479 | I27: =(D27/H27)*100000 -> 11.198735 | J27: =INDEX('Land Area'!$C:$C, MATCH($B27, 'Land Area'!$B:$B, 0)) -> 155779 | K27: =E27/J27 -> 253.64281
A28: California | B28: 6 | C28: 2020 | D28: 32 | E28: 39368078 | F28: 0.1 | H28: 420259 | I28: =(D28/H28)*100000 -> 7.6143521 | J28: =INDEX('Land Area'!$C:$C, MATCH($B28, 'Land Area'!$B:$B, 0)) -> 155779 | K28: =E28/J28 -> 252.71749
A29: California | B29: 6 | C29: 2021 | D29: 41 | E29: 39237836 | F29: 0.1 | H29: 420608 | I29: =(D29/H29)*100000 -> 9.7477937 | J29: =INDEX('Land Area'!$C:$C, MATCH($B29, 'Land Area'!$B:$B, 0)) -> 155779 | K29: =E29/J29 -> 251.88142
A30: California | B30: 6 | C30: 2022 | D30: 52 | E30: 39029342 | F30: 0.1 | H30: 419104 | I30: =(D30/H30)*100000 -> 12.407422 | J30: =INDEX('Land Area'!$C:$C, MATCH($B30, 'Land Area'!$B:$B, 0)) -> 155779 | K30: =E30/J30 -> 250.54303
A31: California | B31: 6 | C31: 2023 | D31: 38 | E31: 38965193 | F31: 0.1 | H31: 400108 | I31: =(D31/H31)*100000 -> 9.4974357 | J31: =INDEX('Land Area'!$C:$C, MATCH($B31, 'Land Area'!$B:$B, 0)) -> 155779 | K31: =E31/J31 -> 250.13123
A32: Colorado | B32: 8 | C32: 2018 | E32: 5695564 | H32: 62885 | J32: =INDEX('Land Area'!$C:$C, MATCH($B32, 'Land Area'!$B:$B, 0)) -> 103642 | K32: =E32/J32 -> 54.954208
A33: Colorado | B33: 8 | C33: 2019 | D33: 12 | E33: 5758736 | F33: 0.2 | G33: Yes | H33: 62869 | I33: =(D33/H33)*100000 -> 19.087309 | J33: =INDEX('Land Area'!$C:$C, MATCH($B33, 'Land Area'!$B:$B, 0)) -> 103642 | K33: =E33/J33 -> 55.563729
A34: Colorado | B34: 8 | C34: 2020 | D34: 10 | E34: 5807719 | F34: 0.2 | G34: Yes | H34: 61494 | I34: =(D34/H34)*100000 -> 16.261749 | J34: =INDEX('Land Area'!$C:$C, MATCH($B34, 'Land Area'!$B:$B, 0)) -> 103642 | K34: =E34/J34 -> 56.036346
A35: Colorado | B35: 8 | C35: 2021 | D35: 11 | E35: 5812069 | F35: 0.2 | G35: Yes | H35: 62949 | I35: =(D35/H35)*100000 -> 17.474463 | J35: =INDEX('Land Area'!$C:$C, MATCH($B35, 'Land Area'!$B:$B, 0)) -> 103642 | K35: =E35/J35 -> 56.078318
A36: Colorado | B36: 8 | C36: 2022 | D36: 12 | E36: 5839926 | F36: 0.2 | G36: Yes | H36: 62383 | I36: =(D36/H36)*100000 -> 19.23601 | J36: =INDEX('Land Area'!$C:$C, MATCH($B36, 'Land Area'!$B:$B, 0)) -> 103642 | K36: =E36/J36 -> 56.347099
A37: Colorado | B37: 8 | C37: 2023 | E37: 5877610 | H37: 61494 | J37: =INDEX('Land Area'!$C:$C, MATCH($B37, 'Land Area'!$B:$B, 0)) -> 103642 | K37: =E37/J37 -> 56.710696
A38: Connecticut | B38: 9 | C38: 2018 | E38: 3572665 | H38: 34725 | J38: =INDEX('Land Area'!$C:$C, MATCH($B38, 'Land Area'!$B:$B, 0)) -> 4842 | K38: =E38/J38 -> 737.84903
A39: Connecticut | B39: 9 | C39: 2019 | E39: 3565287 | H39: 34258 | J39: =INDEX('Land Area'!$C:$C, MATCH($B39, 'Land Area'!$B:$B, 0)) -> 4842 | K39: =E39/J39 -> 736.32528
A40: Connecticut | B40: 9 | C40: 2020 | E40: 3557006 | H40: 33460 | J40: =INDEX('Land Area'!$C:$C, MATCH($B40, 'Land Area'!$B:$B, 0)) -> 4842 | K40: =E40/J40 -> 734.61504
...

Sheet Maternal Deaths 2018-2023
A1: Residence State | B1: FIPS Code | C1: Year | D1: Maternal Deaths | E1: Population | F1: Crude Rate (CR) | G1: CR Unreliable?
A2: Alabama | B2: 1 | C2: 2018 | D2: 21 | E2: 4887871 | F2: 0.4
A3: Alabama | B3: 1 | C3: 2019 | D3: 21 | E3: 4903185 | F3: 0.4
A4: Alabama | B4: 1 | C4: 2020 | D4: 21 | E4: 4921532 | F4: 0.4
A5: Alabama | B5: 1 | C5: 2021 | D5: 33 | E5: 5039877 | F5: 0.7
A6: Alabama | B6: 1 | C6: 2022 | D6: 16 | E6: 5074296 | F6: 0.3 | G6: Yes
A7: Alabama | B7: 1 | C7: 2023 | D7: 11 | E7: 5108468 | F7: 0.2 | G7: Yes
A8: Alaska | B8: 2 | C8: 2018 | D8: Suppressed | E8: 737438 | F8: Suppressed
A9: Alaska | B9: 2 | C9: 2019 | D9: Suppressed | E9: 731545 | F9: Suppressed
A10: Alaska | B10: 2 | C10: 2020 | D10: 0 | E10: 731158 | F10: 0 | G10: Yes
A11: Alaska | B11: 2 | C11: 2021 | D11: Suppressed | E11: 732673 | F11: Suppressed
A12: Alaska | B12: 2 | C12: 2022 | D12: Suppressed | E12: 733583 | F12: Suppressed
A13: Alaska | B13: 2 | C13: 2023 | D13: Suppressed | E13: 733406 | F13: Suppressed
A14: Arizona | B14: 4 | C14: 2018 | D14: 18 | E14: 7171646 | F14: 0.3 | G14: Yes
A15: Arizona | B15: 4 | C15: 2019 | D15: 20 | E15: 7278717 | F15: 0.3
A16: Arizona | B16: 4 | C16: 2020 | D16: 29 | E16: 7421401 | F16: 0.4
A17: Arizona | B17: 4 | C17: 2021 | D17: 32 | E17: 7276316 | F17: 0.4
A18: Arizona | B18: 4 | C18: 2022 | D18: 19 | E18: 7359197 | F18: 0.3 | G18: Yes
A19: Arizona | B19: 4 | C19: 2023 | D19: 19 | E19: 7431344 | F19: 0.3 | G19: Yes
A20: Arkansas | B20: 5 | C20: 2018 | D20: 17 | E20: 3013825 | F20: 0.6 | G20: Yes
A21: Arkansas | B21: 5 | C21: 2019 | D21: 12 | E21: 3017804 | F21: 0.4 | G21: Yes
A22: Arkansas | B22: 5 | C22: 2020 | D22: 15 | E22: 3030522 | F22: 0.5 | G22: Yes
A23: Arkansas | B23: 5 | C23: 2021 | D23: 19 | E23: 3025891 | F23: 0.6 | G23: Yes
A24: Arkansas | B24: 5 | C24: 2022 | D24: Suppressed | E24: 3045637 | F24: Suppressed
A25: Arkansas | B25: 5 | C25: 2023 | D25: 11 | E25: 3067732 | F25: 0.4 | G25: Yes
A26: California | B26: 6 | C26: 2018 | D26: 53 | E26: 39557045 | F26: 0.1
A27: California | B27: 6 | C27: 2019 | D27: 50 | E27: 39512223 | F27: 0.1
A28: California | B28: 6 | C28: 2020 | D28: 32 | E28: 39368078 | F28: 0.1
A29: California | B29: 6 | C29: 2021 | D29: 41 | E29: 39237836 | F29: 0.1
A30: California | B30: 6 | C30: 2022 | D30: 52 | E30: 39029342 | F30: 0.1
A31: California | B31: 6 | C31: 2023 | D31: 38 | E31: 38965193 | F31: 0.1
A32: Colorado | B32: 8 | C32: 2018 | D32: Suppressed | E32: 5695564 | F32: Suppressed
A33: Colorado | B33: 8 | C33: 2019 | D33: 12 | E33: 5758736 | F33: 0.2 | G33: Yes
A34: Colorado | B34: 8 | C34: 2020 | D34: 10 | E34: 5807719 | F34: 0.2 | G34: Yes
A35: Colorado | B35: 8 | C35: 2021 | D35: 11 | E35: 5812069 | F35: 0.2 | G35: Yes
A36: Colorado | B36: 8 | C36: 2022 | D36: 12 | E36: 5839926 | F36: 0.2 | G36: Yes
A37: Colorado | B37: 8 | C37: 2023 | D37: Suppressed | E37: 5877610 | F37: Suppressed
A38: Connecticut | B38: 9 | C38: 2018 | D38: Suppressed | E38: 3572665 | F38: Suppressed
A39: Connecticut | B39: 9 | C39: 2019 | D39: Suppressed | E39: 3565287 | F39: Suppressed
A40: Connecticut | B40: 9 | C40: 2020 | D40: Suppressed | E40: 3557006 | F40: Suppressed
...

Sheet Births 2018-2023
A1: State of Residence | B1: FIPS Code | C1: Year | D1: Births
A2: Alabama | B2: 1 | C2: 2018 | D2: 57761
A3: Alabama | B3: 1 | C3: 2019 | D3: 58615
A4: Alabama | B4: 1 | C4: 2020 | D4: 57647
A5: Alabama | B5: 1 | C5: 2021 | D5: 58054
A6: Alabama | B6: 1 | C6: 2022 | D6: 58149
A7: Alabama | B7: 1 | C7: 2023 | D7: 57858
A8: Alaska | B8: 2 | C8: 2018 | D8: 10086
A9: Alaska | B9: 2 | C9: 2019 | D9: 9822
A10: Alaska | B10: 2 | C10: 2020 | D10: 9469
A11: Alaska | B11: 2 | C11: 2021 | D11: 9367
A12: Alaska | B12: 2 | C12: 2022 | D12: 9359
A13: Alaska | B13: 2 | C13: 2023 | D13: 9015
... A307: Wyoming | B307: 56 | C307: 2023 | D307: 5990

Sheet Land Area
A1: State / District | B1: FIPS | C1: Land area (sq mi) | D1: Land area (sq km)
A2: Alabama | B2: 1 | C2: 52420 | D2: 135767
A3: Alaska | B3: 2 | C3: 571951 | D3: 1481346
A4: Arizona | B4: 4 | C4: 113594 | D4: 294207
A5: Arkansas | B5: 5 | C5: 53179 | D5: 137733
A6: California | B6: 6 | C6: 155779 | D6: 403466
A7: Colorado | B7: 8 | C7: 103642 | D7: 268431
A8: Connecticut | B8: 9 | C8: 4842 | D8: 12543
A9: Delaware | B9: 10 | C9: 1949 | D9: 5047
A10: District of Columbia | B10: 11 | C10: 68 | D10: 176
A11: Florida | B11: 12 | C11: 53625 | D11: 138887
A12: Georgia | B12: 13 | C12: 57513 | D12: 148959
A13: Hawaii | B13: 15 | C13: 6423 | D13: 16639
... A52: Wyoming | B52: 56 | C52: 97093 | D52: 251470
